Workbook
Name Slicer_Representative: #N/A

Sheet Sheet1
A1: Data returned for Call Count, Cleveland, Female (First 1000 rows).
A3: calls[Call number] | B3: calls[Customer ID] | C3: calls[Duration] | D3: calls[Representative] | E3: calls[Date of Call] | F3: calls[Purchase Amount] | G3: calls[Satisfaction Rating] | H3: calls[FY] | I3: calls[Day of week] | J3: calls[Duration Bucket] | K3: calls[Rating rounded] | L3: calls[Date of Call (Month)] | M3: calls[Date of Call (Month Index)]
A4: Call_7277 | B4: C0007 | C4: 84 | D4: R05 | E4: 44929 | F4: 60 | G4: 4.7 | H4: 2023 | I4: Tuesday | J4: 1 to 2 hours | K4: 5 | L4: Jan | M4: 1
A5: Call_7280 | B5: C0010 | C5: 44 | D5: R03 | E5: 44929 | F5: 105 | G5: 2.9 | H5: 2023 | I5: Tuesday | J5: 30 to 60 mins | K5: 3 | L5: Jan | M5: 1
A6: Call_7282 | B6: C0013 | C6: 135 | D6: R05 | E6: 44929 | F6: 46 | G6: 3.4 | H6: 2023 | I6: Tuesday | J6: More than 2 hours | K6: 3 | L6: Jan | M6: 1
A7: Call_7284 | B7: C0010 | C7: 139 | D7: R02 | E7: 44930 | F7: 96 | G7: 4 | H7: 2023 | I7: Wednesday | J7: More than 2 hours | K7: 4 | L7: Jan | M7: 1
A8: Call_7285 | B8: C0013 | C8: 48 | D8: R01 | E8: 44930 | F8: 68 | G8: 4.9 | H8: 2023 | I8: Wednesday | J8: 30 to 60 mins | K8: 5 | L8: Jan | M8: 1
A9: Call_7286 | B9: C0010 | C9: 176 | D9: R05 | E9: 44931 | F9: 24 | G9: 4.8 | H9: 2023 | I9: Thursday | J9: More than 2 hours | K9: 5 | L9: Jan | M9: 1
A10: Call_7287 | B10: C0010 | C10: 99 | D10: R01 | E10: 44931 | F10: 195 | G10: 3.9 | H10: 2023 | I10: Thursday | J10: 1 to 2 hours | K10: 4 | L10: Jan | M10: 1
A11: Call_7289 | B11: C0007 | C11: 54 | D11: R02 | E11: 44931 | F11: 170 | G11: 4.3 | H11: 2023 | I11: Thursday | J11: 30 to 60 mins | K11: 4 | L11: Jan | M11: 1
A12: Call_7294 | B12: C0015 | C12: 58 | D12: R02 | E12: 44934 | F12: 140 | G12: 2.1 | H12: 2023 | I12: Sunday | J12: 30 to 60 mins | K12: 2 | L12: Jan | M12: 1
A13: Call_7295 | B13: C0010 | C13: 54 | D13: R01 | E13: 44934 | F13: 111 | G13: 3.3 | H13: 2023 | I13: Sunday | J13: 30 to 60 mins | K13: 3 | L13: Jan | M13: 1
A14: Call_7300 | B14: C0015 | C14: 155 | D14: R01 | E14: 44936 | F14: 110 | G14: 4.8 | H14: 2023 | I14: Tuesday | J14: More than 2 hours | K14: 5 | L14: Jan | M14: 1
A15: Call_7307 | B15: C0015 | C15: 94 | D15: R03 | E15: 44942 | F15: 120 | G15: 3.1 | H15: 2023 | I15: Monday | J15: 1 to 2 hours | K15: 3 | L15: Jan | M15: 1
... A329: Call_8269 | B329: C0010 | C329: 123 | D329: R05 | E329: 45291 | F329: 64 | G329: 3.7 | H329: 2024 | I329: Sunday | J329: More than 2 hours | K329: 4 | L329: Dec | M329: 12

Sheet Sheet2
A1: Data returned for Call Count, Female (First 1000 rows).
A3: calls[Call number] | B3: calls[Customer ID] | C3: calls[Duration] | D3: calls[Representative] | E3: calls[Date of Call] | F3: calls[Purchase Amount] | G3: calls[Satisfaction Rating] | H3: calls[FY] | I3: calls[Day of week] | J3: calls[Duration Bucket] | K3: calls[Rating rounded] | L3: calls[Date of Call (Month)] | M3: calls[Date of Call (Month Index)]
A4: Call_7274 | B4: C0014 | C4: 119 | D4: R02 | E4: 44927 | F4: 22 | G4: 2.9 | H4: 2023 | I4: Sunday | J4: 1 to 2 hours | K4: 3 | L4: Jan | M4: 1
A5: Call_7275 | B5: C0011 | C5: 128 | D5: R01 | E5: 44928 | F5: 31 | G5: 2.8 | H5: 2023 | I5: Monday | J5: More than 2 hours | K5: 3 | L5: Jan | M5: 1
A6: Call_7276 | B6: C0011 | C6: 49 | D6: R02 | E6: 44929 | F6: 135 | G6: 4.8 | H6: 2023 | I6: Tuesday | J6: 30 to 60 mins | K6: 5 | L6: Jan | M6: 1
A7: Call_7277 | B7: C0007 | C7: 84 | D7: R05 | E7: 44929 | F7: 60 | G7: 4.7 | H7: 2023 | I7: Tuesday | J7: 1 to 2 hours | K7: 5 | L7: Jan | M7: 1
A8: Call_7280 | B8: C0010 | C8: 44 | D8: R03 | E8: 44929 | F8: 105 | G8: 2.9 | H8: 2023 | I8: Tuesday | J8: 30 to 60 mins | K8: 3 | L8: Jan | M8: 1
A9: Call_7281 | B9: C0011 | C9: 102 | D9: R02 | E9: 44929 | F9: 69 | G9: 4.9 | H9: 2023 | I9: Tuesday | J9: 1 to 2 hours | K9: 5 | L9: Jan | M9: 1
A10: Call_7282 | B10: C0013 | C10: 135 | D10: R05 | E10: 44929 | F10: 46 | G10: 3.4 | H10: 2023 | I10: Tuesday | J10: More than 2 hours | K10: 3 | L10: Jan | M10: 1
A11: Call_7284 | B11: C0010 | C11: 139 | D11: R02 | E11: 44930 | F11: 96 | G11: 4 | H11: 2023 | I11: Wednesday | J11: More than 2 hours | K11: 4 | L11: Jan | M11: 1
A12: Call_7285 | B12: C0013 | C12: 48 | D12: R01 | E12: 44930 | F12: 68 | G12: 4.9 | H12: 2023 | I12: Wednesday | J12: 30 to 60 mins | K12: 5 | L12: Jan | M12: 1
A13: Call_7286 | B13: C0010 | C13: 176 | D13: R05 | E13: 44931 | F13: 24 | G13: 4.8 | H13: 2023 | I13: Thursday | J13: More than 2 hours | K13: 5 | L13: Jan | M13: 1
A14: Call_7287 | B14: C0010 | C14: 99 | D14: R01 | E14: 44931 | F14: 195 | G14: 3.9 | H14: 2023 | I14: Thursday | J14: 1 to 2 hours | K14: 4 | L14: Jan | M14: 1
A15: Call_7288 | B15: C0009 | C15: 28 | D15: R03 | E15: 44931 | F15: 28 | G15: 3.8 | H15: 2023 | I15: Thursday | J15: 10 to 30 mins | K15: 4 | L15: Jan | M15: 1
... A602: Call_8270 | B602: C0009 | C602: 114 | D602: R01 | E602: 45291 | F602: 40 | G602: 3.9 | H602: 2024 | I602: Sunday | J602: 1 to 2 hours | K602: 4 | L602: Dec | M602: 12

Sheet Pivots
A3: Call Count | B3: Total Amount | C3: Total Duration | D3: Avg.Rating | E3: 5* Calls
A4: 1000 | B4: 96623 | C4: 89850 | D4: 3.8854 | E4: 307
A7: Call Count | B7: Total Amount | C7: Total Duration | D7: Avg.Rating | E7: 5* Calls
A8: 189 | B8: 18415 | C8: 16834 | D8: 3.9227513 | E8: 60
A12: Row Labels | B12: Call Count | C12: Call Count2 | E12: Row Labels | F12: Call Count
A13: Jan | B13: 16 | C13: 16 | E13: Sunday | F13: 36
A14: Feb | B14: 14 | C14: 14 | E14: Monday | F14: 30
A15: Mar | B15: 26 | C15: 26 | E15: Tuesday | F15: 13
A16: Apr | B16: 29 | C16: 29 | E16: Wednesday | F16: 23
A17: May | B17: 17 | C17: 17 | E17: Thursday | F17: 23
A18: Jun | B18: 15 | C18: 15 | E18: Friday | F18: 24
A19: Jul | B19: 15 | C19: 15 | E19: Saturday | F19: 40
A20: Aug | B20: 7 | C20: 7 | E20: Grand Total | F20: 189
A21: Sep | B21: 11 | C21: 11
A22: Oct | B22: 24 | C22: 24
A23: Nov | B23: 9 | C23: 9
A24: Dec | B24: 6 | C24: 6
A25: Grand Total | B25: 189 | C25: 189
H28: =A43 -> R01
A29: Row Labels | B29: Call Count | C29: Total Amount | E29: Rep | F29: Call Count | G29: Amount | H29: sel.calls | I29: sel.amount
A30: R01 | B30: 189 | C30: 18415 | E30: R01 | F30: 189 | G30: 18415 | H30: =IF(E30=$H$28,F30,NA()) -> 189 | I30: =IF(E30=$H$28,G30,NA()) -> 18415
A31: R02 | B31: 218 | C31: 20581 | E31: R02 | F31: 218 | G31: 20581 | H31: =IF(E31=$H$28,F31,NA()) -> #N/A | I31: =IF(E31=$H$28,G31,NA()) -> #N/A
A32: R03 | B32: 207 | C32: 20872 | E32: R03 | F32: 207 | G32: 20872 | H32: =IF(E32=$H$28,F32,NA()) -> #N/A | I32: =IF(E32=$H$28,G32,NA()) -> #N/A
A33: R04 | B33: 186 | C33: 16651 | E33: R04 | F33: 186 | G33: 16651 | H33: =IF(E33=$H$28,F33,NA()) -> #N/A | I33: =IF(E33=$H$28,G33,NA()) -> #N/A
A34: R05 | B34: 200 | C34: 20104 | E34: R05 | F34: 200 | G34: 20104 | H34: =IF(E34=$H$28,F34,NA()) -> #N/A | I34: =IF(E34=$H$28,G34,NA()) -> #N/A
A35: Grand Total | B35: 1000 | C35: 96623
A42: Row Labels | C42: Call Count | D42: Column Labels | H42: Row Labels | I42: Call Count | K42: Rep Summary
A43: R01 | C43: Row Labels | D43: Female | E43: Male | F43: Grand Total | H43: 1 | I43: 1 | K43: % of calls | L43: =A8/A4 -> 0.189
C44: Cincinnati | D44: 144 | E44: 132 | F44: 276 | H44: 2 | I44: 9
C45: Cleveland | D45: 326 | E45: 63 | F45: 389 | H45: 3 | I45: 31 | K45: Calls | L45: =_xlfn.XLOOKUP(A43,E30:E34,F30:F34) -> 189
C46: Columbus | D46: 129 | E46: 206 | F46: 335 | H46: 4 | I46: 88 | K46: Amount | L46: =_xlfn.XLOOKUP(A43,E30:E34,G30:G34) -> 18415
C47: Grand Total | D47: 599 | E47: 401 | F47: 1000 | H47: 5 | I47: 60
H48: Grand Total | I48: 189 | K48: Call Rank | L48: =_xlfn.RANK.AVG(L45,F30:F34) -> 4
K49: Amount Rank | L49: =_xlfn.RANK.AVG(L46,G30:G34) -> 4
A51: Total Amount | B51: Column Labels | K51: Labels:
A52: Row Labels | B52: R01 | C52: R02 | D52: R03 | E52: R04 | F52: R05 | G52: Grand Total | L52: ="% of Calls:"&TEXT(L43,"0%") -> % of Calls:19%
A53: Cincinnati | L53: =IF(COUNTA(A43:A47)>1,"","Call Rank:"&L48) -> Call Rank:4
A54: C0003 | B54: 891 | C54: 1332 | D54: 1282 | E54: 739 | F54: 560 | G54: 4804 | L54: =IF(COUNTA(A43:A47)>1,"","Amount Rank:"&L49) -> Amount Rank:4
A55: C0004 | B55: 1991 | C55: 1886 | D55: 1206 | E55: 884 | F55: 1722 | G55: 7689
A56: C0011 | B56: 1163 | C56: 1180 | D56: 1616 | E56: 1043 | F56: 1747 | G56: 6749 | K56: Image: | L56: =_xlfn.XLOOKUP(A43,Assets!$E$3:$E$7,Assets!$F$3:$F$7) -> #VALUE!
...

Sheet Data
B1: Call Centre Data
B3: Call number | C3: Customer ID | D3: Duration | E3: Representative | F3: Date of Call | G3: Purchase Amount | H3: Satisfaction Rating | I3: FY | J3: Day of week | K3: Duration Bucket | L3: Rating rounded | Q3: Customer ID | R3: Gender | S3: Age | T3: City
B4: Call_7271 | C4: C0003 | D4: 116 | E4: R05 | F4: 44927 | G4: 128 | H4: 4.9 | I4: =IF(MONTH(calls[[#This Row],[Date of Call]])<=6, YEAR(calls[[#This Row],[Date of Call]]), YEAR(calls[[#This Row],[Date of Call]])+1) -> 2023 | J4: =TEXT(calls[[#This Row],[Date of Call]],"DDDD") -> Sunday | K4: {=_xlfn.IFS(calls[[#This Row],[Duration]]<=10,"Under 10 mins", calls[[#This Row],[Duration]]<=30, "10 to 30 mins", calls[[#This Row],[Duration]]<=60, "30 to 60 mins", calls[[#This Row],[Duration]]<=120, "1 to 2 hours", TRUE, "More than 2 hours")} -> 1 to 2 hours | L4: =ROUND(calls[[#This Row],[Satisfaction Rating]],0) -> 5 | Q4: C0001 | R4: Male | S4: 41 | T4: Columbus
B5: Call_7272 | C5: C0004 | D5: 119 | E5: R05 | F5: 44927 | G5: 135 | H5: 2.9 | I5: =IF(MONTH(calls[[#This Row],[Date of Call]])<=6, YEAR(calls[[#This Row],[Date of Call]]), YEAR(calls[[#This Row],[Date of Call]])+1) -> 2023 | J5: =TEXT(calls[[#This Row],[Date of Call]],"DDDD") -> Sunday | K5: {=_xlfn.IFS(calls[[#This Row],[Duration]]<=10,"Under 10 mins", calls[[#This Row],[Duration]]<=30, "10 to 30 mins", calls[[#This Row],[Duration]]<=60, "30 to 60 mins", calls[[#This Row],[Duration]]<=120, "1 to 2 hours", TRUE, "More than 2 hours")} -> 1 to 2 hours | L5: =ROUND(calls[[#This Row],[Satisfaction Rating]],0) -> 3 | Q5: C0002 | R5: Male | S5: 31 | T5: Cleveland
B6: Call_7273 | C6: C0005 | D6: 68 | E6: R02 | F6: 44927 | G6: 66 | H6: 4.7 | I6: =IF(MONTH(calls[[#This Row],[Date of Call]])<=6, YEAR(calls[[#This Row],[Date of Call]]), YEAR(calls[[#This Row],[Date of Call]])+1) -> 2023 | J6: =TEXT(calls[[#This Row],[Date of Call]],"DDDD") -> Sunday | K6: {=_xlfn.IFS(calls[[#This Row],[Duration]]<=10,"Under 10 mins", calls[[#This Row],[Duration]]<=30, "10 to 30 mins", calls[[#This Row],[Duration]]<=60, "30 to 60 mins", calls[[#This Row],[Duration]]<=120, "1 to 2 hours", TRUE, "More than 2 hours")} -> 1 to 2 hours | L6: =ROUND(calls[[#This Row],[Satisfaction Rating]],0) -> 5 | Q6: C0003 | R6: Male | S6: 26 | T6: Cincinnati
B7: Call_7274 | C7: C0014 | D7: 119 | E7: R02 | F7: 44927 | G7: 22 | H7: 2.9 | I7: =IF(MONTH(calls[[#This Row],[Date of Call]])<=6, YEAR(calls[[#This Row],[Date of Call]]), YEAR(calls[[#This Row],[Date of Call]])+1) -> 2023 | J7: =TEXT(calls[[#This Row],[Date of Call]],"DDDD") -> Sunday | K7: {=_xlfn.IFS(calls[[#This Row],[Duration]]<=10,"Under 10 mins", calls[[#This Row],[Duration]]<=30, "10 to 30 mins", calls[[#This Row],[Duration]]<=60, "30 to 60 mins", calls[[#This Row],[Duration]]<=120, "1 to 2 hours", TRUE, "More than 2 hours")} -> 1 to 2 hours | L7: =ROUND(calls[[#This Row],[Satisfaction Rating]],0) -> 3 | Q7: C0004 | R7: Male | S7: 36 | T7: Cincinnati
B8: Call_7275 | C8: C0011 | D8: 128 | E8: R01 | F8: 44928 | G8: 31 | H8: 2.8 | I8: =IF(MONTH(calls[[#This Row],[Date of Call]])<=6, YEAR(calls[[#This Row],[Date of Call]]), YEAR(calls[[#This Row],[Date of Call]])+1) -> 2023 | J8: =TEXT(calls[[#This Row],[Date of Call]],"DDDD") -> Monday | K8: {=_xlfn.IFS(calls[[#This Row],[Duration]]<=10,"Under 10 mins", calls[[#This Row],[Duration]]<=30, "10 to 30 mins", calls[[#This Row],[Duration]]<=60, "30 to 60 mins", calls[[#This Row],[Duration]]<=120, "1 to 2 hours", TRUE, "More than 2 hours")} -> More than 2 hours | L8: =ROUND(calls[[#This Row],[Satisfaction Rating]],0) -> 3 | Q8: C0005 | R8: Male | S8: 37 | T8: Columbus
B9: Call_7276 | C9: C0011 | D9: 49 | E9: R02 | F9: 44929 | G9: 135 | H9: 4.8 | I9: =IF(MONTH(calls[[#This Row],[Date of Call]])<=6, YEAR(calls[[#This Row],[Date of Call]]), YEAR(calls[[#This Row],[Date of Call]])+1) -> 2023 | J9: =TEXT(calls[[#This Row],[Date of Call]],"DDDD") -> Tuesday | K9: {=_xlfn.IFS(calls[[#This Row],[Duration]]<=10,"Under 10 mins", calls[[#This Row],[Duration]]<=30, "10 to 30 mins", calls[[#This Row],[Duration]]<=60, "30 to 60 mins", calls[[#This Row],[Duration]]<=120, "1 to 2 hours", TRUE, "More than 2 hours")} -> 30 to 60 mins | L9: =ROUND(calls[[#This Row],[Satisfaction Rating]],0) -> 5 | Q9: C0006 | R9: Male | S9: 23 | T9: Columbus
B10: Call_7277 | C10: C0007 | D10: 84 | E10: R05 | F10: 44929 | G10: 60 | H10: 4.7 | I10: =IF(MONTH(calls[[#This Row],[Date of Call]])<=6, YEAR(calls[[#This Row],[Date of Call]]), YEAR(calls[[#This Row],[Date of Call]])+1) -> 2023 | J10: =TEXT(calls[[#This Row],[Date of Call]],"DDDD") -> Tuesday | K10: {=_xlfn.IFS(calls[[#This Row],[Duration]]<=10,"Under 10 mins", calls[[#This Row],[Duration]]<=30, "10 to 30 mins", calls[[#This Row],[Duration]]<=60, "30 to 60 mins", calls[[#This Row],[Duration]]<=120, "1 to 2 hours", TRUE, "More than 2 hours")} -> 1 to 2 hours | L10: =ROUND(calls[[#This Row],[Satisfaction Rating]],0) -> 5 | Q10: C0007 | R10: Female | S10: 22 | T10: Cleveland
B11: Call_7278 | C11: C0003 | D11: 103 | E11: R04 | F11: 44929 | G11: 148 | H11: 4.4 | I11: =IF(MONTH(calls[[#This Row],[Date of Call]])<=6, YEAR(calls[[#This Row],[Date of Call]]), YEAR(calls[[#This Row],[Date of Call]])+1) -> 2023 | J11: =TEXT(calls[[#This Row],[Date of Call]],"DDDD") -> Tuesday | K11: {=_xlfn.IFS(calls[[#This Row],[Duration]]<=10,"Under 10 mins", calls[[#This Row],[Duration]]<=30, "10 to 30 mins", calls[[#This Row],[Duration]]<=60, "30 to 60 mins", calls[[#This Row],[Duration]]<=120, "1 to 2 hours", TRUE, "More than 2 hours")} -> 1 to 2 hours | L11: =ROUND(calls[[#This Row],[Satisfaction Rating]],0) -> 4 | Q11: C0008 | R11: Female | S11: 42 | T11: Cleveland
B12: Call_7279 | C12: C0005 | D12: 31 | E12: R02 | F12: 44929 | G12: 135 | H12: 3.6 | I12: =IF(MONTH(calls[[#This Row],[Date of Call]])<=6, YEAR(calls[[#This Row],[Date of Call]]), YEAR(calls[[#This Row],[Date of Call]])+1) -> 2023 | J12: =TEXT(calls[[#This Row],[Date of Call]],"DDDD") -> Tuesday | K12: {=_xlfn.IFS(calls[[#This Row],[Duration]]<=10,"Under 10 mins", calls[[#This Row],[Duration]]<=30, "10 to 30 mins", calls[[#This Row],[Duration]]<=60, "30 to 60 mins", calls[[#This Row],[Duration]]<=120, "1 to 2 hours", TRUE, "More than 2 hours")} -> 30 to 60 mins | L12: =ROUND(calls[[#This Row],[Satisfaction Rating]],0) -> 4 | Q12: C0009 | R12: Female | S12: 25 | T12: Columbus
B13: Call_7280 | C13: C0010 | D13: 44 | E13: R03 | F13: 44929 | G13: 105 | H13: 2.9 | I13: =IF(MONTH(calls[[#This Row],[Date of Call]])<=6, YEAR(calls[[#This Row],[Date of Call]]), YEAR(calls[[#This Row],[Date of Call]])+1) -> 2023 | J13: =TEXT(calls[[#This Row],[Date of Call]],"DDDD") -> Tuesday | K13: {=_xlfn.IFS(calls[[#This Row],[Duration]]<=10,"Under 10 mins", calls[[#This Row],[Duration]]<=30, "10 to 30 mins", calls[[#This Row],[Duration]]<=60, "30 to 60 mins", calls[[#This Row],[Duration]]<=120, "1 to 2 hours", TRUE, "More than 2 hours")} -> 30 to 60 mins | L13: =ROUND(calls[[#This Row],[Satisfaction Rating]],0) -> 3 | Q13: C0010 | R13: Female | S13: 30 | T13: Cleveland
B14: Call_7281 | C14: C0011 | D14: 102 | E14: R02 | F14: 44929 | G14: 69 | H14: 4.9 | I14: =IF(MONTH(calls[[#This Row],[Date of Call]])<=6, YEAR(calls[[#This Row],[Date of Call]]), YEAR(calls[[#This Row],[Date of Call]])+1) -> 2023 | J14: =TEXT(calls[[#This Row],[Date of Call]],"DDDD") -> Tuesday | K14: {=_xlfn.IFS(calls[[#This Row],[Duration]]<=10,"Under 10 mins", calls[[#This Row],[Duration]]<=30, "10 to 30 mins", calls[[#This Row],[Duration]]<=60, "30 to 60 mins", calls[[#This Row],[Duration]]<=120, "1 to 2 hours", TRUE, "More than 2 hours")} -> 1 to 2 hours | L14: =ROUND(calls[[#This Row],[Satisfaction Rating]],0) -> 5 | Q14: C0011 | R14: Female | S14: 30 | T14: Cincinnati
B15: Call_7282 | C15: C0013 | D15: 135 | E15: R05 | F15: 44929 | G15: 46 | H15: 3.4 | I15: =IF(MONTH(calls[[#This Row],[Date of Call]])<=6, YEAR(calls[[#This Row],[Date of Call]]), YEAR(calls[[#This Row],[Date of Call]])+1) -> 2023 | J15: =TEXT(calls[[#This Row],[Date of Call]],"DDDD") -> Tuesday | K15: {=_xlfn.IFS(calls[[#This Row],[Duration]]<=10,"Under 10 mins", calls[[#This Row],[Duration]]<=30, "10 to 30 mins", calls[[#This Row],[Duration]]<=60, "30 to 60 mins", calls[[#This Row],[Duration]]<=120, "1 to 2 hours", TRUE, "More than 2 hours")} -> More than 2 hours | L15: =ROUND(calls[[#This Row],[Satisfaction Rating]],0) -> 3 | Q15: C0012 | R15: Female | S15: 28 | T15: Cincinnati
... B18: Call_7285 | C18: C0013 | D18: 48 | E18: R01 | F18: 44930 | G18: 68 | H18: 4.9 | I18: =IF(MONTH(calls[[#This Row],[Date of Call]])<=6, YEAR(calls[[#This Row],[Date of Call]]), YEAR(calls[[#This Row],[Date of Call]])+1) -> 2023 | J18: =TEXT(calls[[#This Row],[Date of Call]],"DDDD") -> Wednesday | K18: {=_xlfn.IFS(calls[[#This Row],[Duration]]<=10,"Under 10 mins", calls[[#This Row],[Duration]]<=30, "10 to 30 mins", calls[[#This Row],[Duration]]<=60, "30 to 60 mins", calls[[#This Row],[Duration]]<=120, "1 to 2 hours", TRUE, "More than 2 hours")} -> 30 to 60 mins | L18: =ROUND(calls[[#This Row],[Satisfaction Rating]],0) -> 5 | Q18: C0015 | R18: Female | S18: 43 | T18: Cleveland
B19: Call_7286 | C19: C0010 | D19: 176 | E19: R05 | F19: 44931 | G19: 24 | H19: 4.8 | I19: =IF(MONTH(calls[[#This Row],[Date of Call]])<=6, YEAR(calls[[#This Row],[Date of Call]]), YEAR(calls[[#This Row],[Date of Call]])+1) -> 2023 | J19: =TEXT(calls[[#This Row],[Date of Call]],"DDDD") -> Thursday | K19: {=_xlfn.IFS(calls[[#This Row],[Duration]]<=10,"Under 10 mins", calls[[#This Row],[Duration]]<=30, "10 to 30 mins", calls[[#This Row],[Duration]]<=60, "30 to 60 mins", calls[[#This Row],[Duration]]<=120, "1 to 2 hours", TRUE, "More than 2 hours")} -> More than 2 hours | L19: =ROUND(calls[[#This Row],[Satisfaction Rating]],0) -> 5
B20: Call_7287 | C20: C0010 | D20: 99 | E20: R01 | F20: 44931 | G20: 195 | H20: 3.9 | I20: =IF(MONTH(calls[[#This Row],[Date of Call]])<=6, YEAR(calls[[#This Row],[Date of Call]]), YEAR(calls[[#This Row],[Date of Call]])+1) -> 2023 | J20: =TEXT(calls[[#This Row],[Date of Call]],"DDDD") -> Thursday | K20: {=_xlfn.IFS(calls[[#This Row],[Duration]]<=10,"Under 10 mins", calls[[#This Row],[Duration]]<=30, "10 to 30 mins", calls[[#This Row],[Duration]]<=60, "30 to 60 mins", calls[[#This Row],[Duration]]<=120, "1 to 2 hours", TRUE, "More than 2 hours")} -> 1 to 2 hours | L20: =ROUND(calls[[#This Row],[Satisfaction Rating]],0) -> 4
B21: Call_7288 | C21: C0009 | D21: 28 | E21: R03 | F21: 44931 | G21: 28 | H21: 3.8 | I21: =IF(MONTH(calls[[#This Row],[Date of Call]])<=6, YEAR(calls[[#This Row],[Date of Call]]), YEAR(calls[[#This Row],[Date of Call]])+1) -> 2023 | J21: =TEXT(calls[[#This Row],[Date of Call]],"DDDD") -> Thursday | K21: {=_xlfn.IFS(calls[[#This Row],[Duration]]<=10,"Under 10 mins", calls[[#This Row],[Duration]]<=30, "10 to 30 mins", calls[[#This Row],[Duration]]<=60, "30 to 60 mins", calls[[#This Row],[Duration]]<=120, "1 to 2 hours", TRUE, "More than 2 hours")} -> 10 to 30 mins | L21: =ROUND(calls[[#This Row],[Satisfaction Rating]],0) -> 4
B22: Call_7289 | C22: C0007 | D22: 54 | E22: R02 | F22: 44931 | G22: 170 | H22: 4.3 | I22: =IF(MONTH(calls[[#This Row],[Date of Call]])<=6, YEAR(calls[[#This Row],[Date of Call]]), YEAR(calls[[#This Row],[Date of Call]])+1) -> 2023 | J22: =TEXT(calls[[#This Row],[Date of Call]],"DDDD") -> Thursday | K22: {=_xlfn.IFS(calls[[#This Row],[Duration]]<=10,"Under 10 mins", calls[[#This Row],[Duration]]<=30, "10 to 30 mins", calls[[#This Row],[Duration]]<=60, "30 to 60 mins", calls[[#This Row],[Duration]]<=120, "1 to 2 hours", TRUE, "More than 2 hours")} -> 30 to 60 mins | L22: =ROUND(calls[[#This Row],[Satisfaction Rating]],0) -> 4
B23: Call_7290 | C23: C0006 | D23: 48 | E23: R05 | F23: 44932 | G23: 30 | H23: 4.4 | I23: =IF(MONTH(calls[[#This Row],[Date of Call]])<=6, YEAR(calls[[#This Row],[Date of Call]]), YEAR(calls[[#This Row],[Date of Call]])+1) -> 2023 | J23: =TEXT(calls[[#This Row],[Date of Call]],"DDDD") -> Friday | K23: {=_xlfn.IFS(calls[[#This Row],[Duration]]<=10,"Under 10 mins", calls[[#This Row],[Duration]]<=30, "10 to 30 mins", calls[[#This Row],[Duration]]<=60, "30 to 60 mins", calls[[#This Row],[Duration]]<=120, "1 to 2 hours", TRUE, "More than 2 hours")} -> 30 to 60 mins | L23: =ROUND(calls[[#This Row],[Satisfaction Rating]],0) -> 4
B24: Call_7291 | C24: C0004 | D24: 128 | E24: R05 | F24: 44932 | G24: 72 | H24: 5 | I24: =IF(MONTH(calls[[#This Row],[Date of Call]])<=6, YEAR(calls[[#This Row],[Date of Call]]), YEAR(calls[[#This Row],[Date of Call]])+1) -> 2023 | J24: =TEXT(calls[[#This Row],[Date of Call]],"DDDD") -> Friday | K24: {=_xlfn.IFS(calls[[#This Row],[Duration]]<=10,"Under 10 mins", calls[[#This Row],[Duration]]<=30, "10 to 30 mins", calls[[#This Row],[Duration]]<=60, "30 to 60 mins", calls[[#This Row],[Duration]]<=120, "1 to 2 hours", TRUE, "More than 2 hours")} -> More than 2 hours | L24: =ROUND(calls[[#This Row],[Satisfaction Rating]],0) -> 5
B25: Call_7292 | C25: C0004 | D25: 38 | E25: R04 | F25: 44933 | G25: 92 | H25: 4.9 | I25: =IF(MONTH(calls[[#This Row],[Date of Call]])<=6, YEAR(calls[[#This Row],[Date of Call]]), YEAR(calls[[#This Row],[Date of Call]])+1) -> 2023 | J25: =TEXT(calls[[#This Row],[Date of Call]],"DDDD") -> Saturday | K25: {=_xlfn.IFS(calls[[#This Row],[Duration]]<=10,"Under 10 mins", calls[[#This Row],[Duration]]<=30, "10 to 30 mins", calls[[#This Row],[Duration]]<=60, "30 to 60 mins", calls[[#This Row],[Duration]]<=120, "1 to 2 hours", TRUE, "More than 2 hours")} -> 30 to 60 mins | L25: =ROUND(calls[[#This Row],[Satisfaction Rating]],0) -> 5
B26: Call_7293 | C26: C0003 | D26: 67 | E26: R04 | F26: 44934 | G26: 165 | H26: 4.5 | I26: =IF(MONTH(calls[[#This Row],[Date of Call]])<=6, YEAR(calls[[#This Row],[Date of Call]]), YEAR(calls[[#This Row],[Date of Call]])+1) -> 2023 | J26: =TEXT(calls[[#This Row],[Date of Call]],"DDDD") -> Sunday | K26: {=_xlfn.IFS(calls[[#This Row],[Duration]]<=10,"Under 10 mins", calls[[#This Row],[Duration]]<=30, "10 to 30 mins", calls[[#This Row],[Duration]]<=60, "30 to 60 mins", calls[[#This Row],[Duration]]<=120, "1 to 2 hours", TRUE, "More than 2 hours")} -> 1 to 2 hours | L26: =ROUND(calls[[#This Row],[Satisfaction Rating]],0) -> 5
B27: Call_7294 | C27: C0015 | D27: 58 | E27: R02 | F27: 44934 | G27: 140 | H27: 2.1 | I27: =IF(MONTH(calls[[#This Row],[Date of Call]])<=6, YEAR(calls[[#This Row],[Date of Call]]), YEAR(calls[[#This Row],[Date of Call]])+1) -> 2023 | J27: =TEXT(calls[[#This Row],[Date of Call]],"DDDD") -> Sunday | K27: {=_xlfn.IFS(calls[[#This Row],[Duration]]<=10,"Under 10 mins", calls[[#This Row],[Duration]]<=30, "10 to 30 mins", calls[[#This Row],[Duration]]<=60, "30 to 60 mins", calls[[#This Row],[Duration]]<=120, "1 to 2 hours", TRUE, "More than 2 hours")} -> 30 to 60 mins | L27: =ROUND(calls[[#This Row],[Satisfaction Rating]],0) -> 2
B28: Call_7295 | C28: C0010 | D28: 54 | E28: R01 | F28: 44934 | G28: 111 | H28: 3.3 | I28: =IF(MONTH(calls[[#This Row],[Date of Call]])<=6, YEAR(calls[[#This Row],[Date of Call]]), YEAR(calls[[#This Row],[Date of Call]])+1) -> 2023 | J28: =TEXT(calls[[#This Row],[Date of Call]],"DDDD") -> Sunday | K28: {=_xlfn.IFS(calls[[#This Row],[Duration]]<=10,"Under 10 mins", calls[[#This Row],[Duration]]<=30, "10 to 30 mins", calls[[#This Row],[Duration]]<=60, "30 to 60 mins", calls[[#This Row],[Duration]]<=120, "1 to 2 hours", TRUE, "More than 2 hours")} -> 30 to 60 mins | L28: =ROUND(calls[[#This Row],[Satisfaction Rating]],0) -> 3
B29: Call_7296 | C29: C0012 | D29: 28 | E29: R05 | F29: 44935 | G29: 63 | H29: 4.1 | I29: =IF(MONTH(calls[[#This Row],[Date of Call]])<=6, YEAR(calls[[#This Row],[Date of Call]]), YEAR(calls[[#This Row],[Date of Call]])+1) -> 2023 | J29: =TEXT(calls[[#This Row],[Date of Call]],"DDDD") -> Monday | K29: {=_xlfn.IFS(calls[[#This Row],[Duration]]<=10,"Under 10 mins", calls[[#This Row],[Duration]]<=30, "10 to 30 mins", calls[[#This Row],[Duration]]<=60, "30 to 60 mins", calls[[#This Row],[Duration]]<=120, "1 to 2 hours", TRUE, "More than 2 hours")} -> 10 to 30 mins | L29: =ROUND(calls[[#This Row],[Satisfaction Rating]],0) -> 4
B30: Call_7297 | C30: C0002 | D30: 73 | E30: R05 | F30: 44935 | G30: 80 | H30: 4.2 | I30: =IF(MONTH(calls[[#This Row],[Date of Call]])<=6, YEAR(calls[[#This Row],[Date of Call]]), YEAR(calls[[#This Row],[Date of Call]])+1) -> 2023 | J30: =TEXT(calls[[#This Row],[Date of Call]],"DDDD") -> Monday | K30: {=_xlfn.IFS(calls[[#This Row],[Duration]]<=10,"Under 10 mins", calls[[#This Row],[Duration]]<=30, "10 to 30 mins", calls[[#This Row],[Duration]]<=60, "30 to 60 mins", calls[[#This Row],[Duration]]<=120, "1 to 2 hours", TRUE, "More than 2 hours")} -> 1 to 2 hours | L30: =ROUND(calls[[#This Row],[Satisfaction Rating]],0) -> 4
... B1003: Call_8270 | C1003: C0009 | D1003: 114 | E1003: R01 | F1003: 45291 | G1003: 40 | H1003: 3.9 | I1003: =IF(MONTH(calls[[#This Row],[Date of Call]])<=6, YEAR(calls[[#This Row],[Date of Call]]), YEAR(calls[[#This Row],[Date of Call]])+1) -> 2024 | J1003: =TEXT(calls[[#This Row],[Date of Call]],"DDDD") -> Sunday | K1003: {=_xlfn.IFS(calls[[#This Row],[Duration]]<=10,"Under 10 mins", calls[[#This Row],[Duration]]<=30, "10 to 30 mins", calls[[#This Row],[Duration]]<=60, "30 to 60 mins", calls[[#This Row],[Duration]]<=120, "1 to 2 hours", TRUE, "More than 2 hours")} -> 1 to 2 hours | L1003: =ROUND(calls[[#This Row],[Satisfaction Rating]],0) -> 4

Sheet Customer Center Report
J1: CALL CENTRE REPORT
N14: {=Pivots!B52:F52} -> R01 | O14: R02 | P14: R03 | Q14: R04 | R14: R05 | S14: Total
M15: {=IF(Pivots!A53:G70="","",Pivots!A53:G70)} -> Cincinnati
M16: C0003 | N16: 891 | O16: 1332 | P16: 1282 | Q16: 739 | R16: 560 | S16: 4804
M17: C0004 | N17: 1991 | O17: 1886 | P17: 1206 | Q17: 884 | R17: 1722 | S17: 7689
M18: C0011 | N18: 1163 | O18: 1180 | P18: 1616 | Q18: 1043 | R18: 1747 | S18: 6749
M19: C0012 | N19: 1438 | O19: 1616 | P19: 866 | Q19: 829 | R19: 2070 | S19: 6819
M20: Cleveland
M21: C0002 | N21: 1233 | O21: 223 | P21: 1680 | Q21: 990 | R21: 1508 | S21: 5634
M22: C0007 | N22: 1598 | O22: 1907 | P22: 869 | Q22: 1426 | R22: 1416 | S22: 7216
M23: C0008 | N23: 900 | O23: 1016 | P23: 960 | Q23: 940 | R23: 1193 | S23: 5009
M24: C0010 | N24: 900 | O24: 1470 | P24: 1617 | Q24: 1314 | R24: 941 | S24: 6242
J25: =Pivots!L56 -> #VALUE! | M25: C0013 | N25: 1255 | O25: 516 | P25: 1874 | Q25: 1863 | R25: 1722 | S25: 7230
M26: C0015 | N26: 1138 | O26: 1898 | P26: 1482 | Q26: 846 | R26: 1154 | S26: 6518
M27: Columbus
M28: C0001 | N28: 1655 | O28: 805 | P28: 2263 | Q28: 987 | R28: 1075 | S28: 6785
K29: =Pivots!L52 -> % of Calls:19% | M29: C0005 | N29: 1104 | O29: 2280 | P29: 1445 | Q29: 1722 | R29: 1196 | S29: 7747
K30: =Pivots!L53 -> Call Rank:4 | M30: C0006 | N30: 372 | O30: 1818 | P30: 1346 | Q30: 1156 | R30: 1484 | S30: 6176
K31: =Pivots!L54 -> Amount Rank:4 | M31: C0009 | N31: 1415 | O31: 1271 | P31: 1214 | Q31: 1135 | R31: 1566 | S31: 6601
M32: C0014 | N32: 1362 | O32: 1363 | P32: 1152 | Q32: 777 | R32: 750 | S32: 5404

Sheet Assets
E2: Rep ID | F2: Rep Image
E3: R01 | F3: #VALUE!
E4: R02 | F4: #VALUE!
E5: R03 | F5: #VALUE!
E6: R04 | F6: #VALUE!
E7: R05 | F7: #VALUE!
